<?xml version="1.0" encoding="UTF-8"?>
<testng-results ignored="0" total="2" passed="0" failed="2" skipped="0">
  <reporter-output>
  </reporter-output>
  <suite started-at="2024-03-03T02:13:09 IST" name="Default suite" finished-at="2024-03-03T02:14:31 IST" duration-ms="82044">
    <groups>
    </groups>
    <test started-at="2024-03-03T02:13:09 IST" name="Default test" finished-at="2024-03-03T02:14:31 IST" duration-ms="82044">
      <class name="TestCases.Userflow_1">
        <test-method is-config="true" signature="extent_Report()[pri:0, instance:TestCases.Userflow_1@2453f95d]" started-at="2024-03-03T02:13:09 IST" name="extent_Report" finished-at="2024-03-03T02:13:15 IST" duration-ms="5807" status="PASS">
          <reporter-output>
          </reporter-output>
        </test-method> <!-- extent_Report -->
        <test-method signature="TC_1()[pri:1, instance:TestCases.Userflow_1@2453f95d]" started-at="2024-03-03T02:13:15 IST" name="TC_1" finished-at="2024-03-03T02:13:51 IST" duration-ms="35850" status="FAIL">
          <exception class="java.lang.AssertionError">
            <message>
              <![CDATA[null]]>
            </message>
            <full-stacktrace>
              <![CDATA[java.lang.AssertionError: null
at org.testng.Assert.fail(Assert.java:99)
at org.testng.Assert.fail(Assert.java:106)
at CommonMethods.Keywords.click(Keywords.java:72)
at TestCases.Test1.TC_1(Test1.java:13)
at TestCases.Userflow_1.TC_1(Userflow_1.java:49)
at java.base/jdk.internal.reflect.NativeMethodAccessorImpl.invoke0(Native Method)
at java.base/jdk.internal.reflect.NativeMethodAccessorImpl.invoke(NativeMethodAccessorImpl.java:77)
at java.base/jdk.internal.reflect.DelegatingMethodAccessorImpl.invoke(DelegatingMethodAccessorImpl.java:43)
at java.base/java.lang.reflect.Method.invoke(Method.java:568)
at org.testng.internal.MethodInvocationHelper.invokeMethod(MethodInvocationHelper.java:133)
at org.testng.internal.TestInvoker.invokeMethod(TestInvoker.java:598)
at org.testng.internal.TestInvoker.invokeTestMethod(TestInvoker.java:173)
at org.testng.internal.MethodRunner.runInSequence(MethodRunner.java:46)
at org.testng.internal.TestInvoker$MethodInvocationAgent.invoke(TestInvoker.java:824)
at org.testng.internal.TestInvoker.invokeTestMethods(TestInvoker.java:146)
at org.testng.internal.TestMethodWorker.invokeTestMethods(TestMethodWorker.java:146)
at org.testng.internal.TestMethodWorker.run(TestMethodWorker.java:128)
at java.base/java.util.ArrayList.forEach(ArrayList.java:1511)
at org.testng.TestRunner.privateRun(TestRunner.java:794)
at org.testng.TestRunner.run(TestRunner.java:596)
at org.testng.SuiteRunner.runTest(SuiteRunner.java:377)
at org.testng.SuiteRunner.runSequentially(SuiteRunner.java:371)
at org.testng.SuiteRunner.privateRun(SuiteRunner.java:332)
at org.testng.SuiteRunner.run(SuiteRunner.java:276)
at org.testng.SuiteRunnerWorker.runSuite(SuiteRunnerWorker.java:53)
at org.testng.SuiteRunnerWorker.run(SuiteRunnerWorker.java:96)
at org.testng.TestNG.runSuitesSequentially(TestNG.java:1212)
at org.testng.TestNG.runSuitesLocally(TestNG.java:1134)
at org.testng.TestNG.runSuites(TestNG.java:1063)
at org.testng.TestNG.run(TestNG.java:1031)
at org.testng.remote.AbstractRemoteTestNG.run(AbstractRemoteTestNG.java:115)
at org.testng.remote.RemoteTestNG.initAndRun(RemoteTestNG.java:251)
at org.testng.remote.RemoteTestNG.main(RemoteTestNG.java:77)
]]>
            </full-stacktrace>
          </exception> <!-- java.lang.AssertionError -->
          <reporter-output>
          </reporter-output>
        </test-method> <!-- TC_1 -->
        <test-method is-config="true" signature="Teardown(org.testng.ITestResult)[pri:0, instance:TestCases.Userflow_1@2453f95d]" started-at="2024-03-03T02:13:51 IST" name="Teardown" finished-at="2024-03-03T02:13:54 IST" duration-ms="2383" status="PASS">
          <params>
            <param index="0">
              <value>
                <![CDATA[[TestResult name=TC_1 status=FAILURE method=Userflow_1.TC_1()[pri:1, instance:TestCases.Userflow_1@2453f95d] output={null}]]]>
              </value>
            </param>
          </params>
          <reporter-output>
          </reporter-output>
        </test-method> <!-- Teardown -->
        <test-method signature="TC_2()[pri:2, instance:TestCases.Userflow_1@2453f95d]" started-at="2024-03-03T02:13:54 IST" name="TC_2" finished-at="2024-03-03T02:14:28 IST" duration-ms="33916" status="FAIL">
          <exception class="java.lang.AssertionError">
            <message>
              <![CDATA[null]]>
            </message>
            <full-stacktrace>
              <![CDATA[java.lang.AssertionError: null
at org.testng.Assert.fail(Assert.java:99)
at org.testng.Assert.fail(Assert.java:106)
at CommonMethods.Keywords.click(Keywords.java:72)
at TestCases.Test1.TC_2(Test1.java:31)
at TestCases.Userflow_1.TC_2(Userflow_1.java:58)
at java.base/jdk.internal.reflect.NativeMethodAccessorImpl.invoke0(Native Method)
at java.base/jdk.internal.reflect.NativeMethodAccessorImpl.invoke(NativeMethodAccessorImpl.java:77)
at java.base/jdk.internal.reflect.DelegatingMethodAccessorImpl.invoke(DelegatingMethodAccessorImpl.java:43)
at java.base/java.lang.reflect.Method.invoke(Method.java:568)
at org.testng.internal.MethodInvocationHelper.invokeMethod(MethodInvocationHelper.java:133)
at org.testng.internal.TestInvoker.invokeMethod(TestInvoker.java:598)
at org.testng.internal.TestInvoker.invokeTestMethod(TestInvoker.java:173)
at org.testng.internal.MethodRunner.runInSequence(MethodRunner.java:46)
at org.testng.internal.TestInvoker$MethodInvocationAgent.invoke(TestInvoker.java:824)
at org.testng.internal.TestInvoker.invokeTestMethods(TestInvoker.java:146)
at org.testng.internal.TestMethodWorker.invokeTestMethods(TestMethodWorker.java:146)
at org.testng.internal.TestMethodWorker.run(TestMethodWorker.java:128)
at java.base/java.util.ArrayList.forEach(ArrayList.java:1511)
at org.testng.TestRunner.privateRun(TestRunner.java:794)
at org.testng.TestRunner.run(TestRunner.java:596)
at org.testng.SuiteRunner.runTest(SuiteRunner.java:377)
at org.testng.SuiteRunner.runSequentially(SuiteRunner.java:371)
at org.testng.SuiteRunner.privateRun(SuiteRunner.java:332)
at org.testng.SuiteRunner.run(SuiteRunner.java:276)
at org.testng.SuiteRunnerWorker.runSuite(SuiteRunnerWorker.java:53)
at org.testng.SuiteRunnerWorker.run(SuiteRunnerWorker.java:96)
at org.testng.TestNG.runSuitesSequentially(TestNG.java:1212)
at org.testng.TestNG.runSuitesLocally(TestNG.java:1134)
at org.testng.TestNG.runSuites(TestNG.java:1063)
at org.testng.TestNG.run(TestNG.java:1031)
at org.testng.remote.AbstractRemoteTestNG.run(AbstractRemoteTestNG.java:115)
at org.testng.remote.RemoteTestNG.initAndRun(RemoteTestNG.java:251)
at org.testng.remote.RemoteTestNG.main(RemoteTestNG.java:77)
]]>
            </full-stacktrace>
          </exception> <!-- java.lang.AssertionError -->
          <reporter-output>
          </reporter-output>
        </test-method> <!-- TC_2 -->
        <test-method is-config="true" signature="Teardown(org.testng.ITestResult)[pri:0, instance:TestCases.Userflow_1@2453f95d]" started-at="2024-03-03T02:14:28 IST" name="Teardown" finished-at="2024-03-03T02:14:30 IST" duration-ms="2334" status="PASS">
          <params>
            <param index="0">
              <value>
                <![CDATA[[TestResult name=TC_2 status=FAILURE method=Userflow_1.TC_2()[pri:2, instance:TestCases.Userflow_1@2453f95d] output={null}]]]>
              </value>
            </param>
          </params>
          <reporter-output>
          </reporter-output>
        </test-method> <!-- Teardown -->
        <test-method is-config="true" signature="aftertest()[pri:0, instance:TestCases.Userflow_1@2453f95d]" started-at="2024-03-03T02:14:30 IST" name="aftertest" finished-at="2024-03-03T02:14:31 IST" duration-ms="1140" status="PASS">
          <reporter-output>
          </reporter-output>
        </test-method> <!-- aftertest -->
      </class> <!-- TestCases.Userflow_1 -->
    </test> <!-- Default test -->
  </suite> <!-- Default suite -->
</testng-results>
